Workbook

Sheet Sheet1
B1: fid | C1: dataset | D1: vert | E1: Duplicate | F1: Remove | G1: T11 | H1: T13 | I1: Sanity | J1: LabelOverride | K1: DeleteLabel | L1: TLTV | M1: SR_l | N1: SR_r | O1: HE Comment
A2: 0 | B2: ATL009_dir-sag_split-WS | C2: dataset-ATL | D2: 20 | E2: =COUNTIF($B$2:B2, B2) -> 1 | F2: 0 | G2: 0 | H2: 1 | I2: =SUM(G2:H2) -> 1 | L2: 1 | M2: 1 | N2: 1 | O2: SR bds
A3: 1 | B3: ATL022_dir-sag_split-WS | C3: dataset-ATL | D3: 20 | E3: =COUNTIF($B$2:B3, B3) -> 1 | F3: 0 | G3: 0 | H3: 0 | I3: =SUM(G3:H3) -> 0 | L3: 0 | M3: 0 | N3: 0 | O3: Fx, Ribben sind vom drüber
A4: 2 | B4: ATL035_dir-sag_split-WS | C4: dataset-ATL | D4: 20 | E4: =COUNTIF($B$2:B4, B4) -> 1 | F4: 0 | G4: 0 | H4: 1 | I4: =SUM(G4:H4) -> 1 | L4: 1 | M4: 1 | N4: 1 | O4: SR bds
A5: 3 | B5: ATL038_dir-sag_split-WS | C5: dataset-ATL | D5: 20 | E5: =COUNTIF($B$2:B5, B5) -> 1 | F5: 0 | G5: 0 | H5: 0 | I5: =SUM(G5:H5) -> 0 | L5: 0 | M5: 0 | N5: 0 | O5: Keine Rippen
A6: 4 | B6: ATL045_dir-sag_split-LWS | C6: dataset-ATL | D6: 20 | E6: =COUNTIF($B$2:B6, B6) -> 1 | F6: 0 | G6: 0 | H6: 1 | I6: =SUM(G6:H6) -> 1 | L6: 1 | M6: 1 | N6: 1 | O6: SR bds
A7: 5 | B7: ATL058_dir-sag_split-WS | C7: dataset-ATL | D7: 20 | E7: =COUNTIF($B$2:B7, B7) -> 1 | F7: 0 | G7: 0 | H7: 0 | I7: =SUM(G7:H7) -> 0 | L7: 1 | M7: 0 | N7: 0 | O7: Type 4 → Lumbar
A8: 6 | B8: ATL075_dir-sag_split-BWSLWS | C8: dataset-ATL | D8: 20 | E8: =COUNTIF($B$2:B8, B8) -> 1 | F8: 0 | G8: 0 | H8: 1 | I8: =SUM(G8:H8) -> 1 | L8: 1 | M8: 1 | N8: 1 | O8: SR bds
A9: 7 | B9: ATL109_dir-sag_split-BWSLWS | C9: dataset-ATL | D9: 20 | E9: =COUNTIF($B$2:B9, B9) -> 1 | F9: 0 | G9: 0 | H9: 1 | I9: =SUM(G9:H9) -> 1 | L9: 1 | M9: 1 | N9: 1 | O9: Verwachsen mit costalis? Würde T13 + SR bds sagen
A10: 8 | B10: ATL154_dir-sag_split-WS | C10: dataset-ATL | D10: 20 | E10: =COUNTIF($B$2:B10, B10) -> 1 | F10: 0 | G10: 0 | H10: 0 | I10: =SUM(G10:H10) -> 0 | L10: 0 | M10: 0 | N10: 0 | O10: Keine Rippen
A11: 9 | B11: ATL202_dir-sag | C11: dataset-ATL | D11: 20 | E11: =COUNTIF($B$2:B11, B11) -> 1 | F11: 0 | G11: 0 | H11: 1 | I11: =SUM(G11:H11) -> 1 | L11: 1 | M11: 1 | N11: 1 | O11: SR bds
A12: 10 | B12: ATL211_dir-sag | C12: dataset-ATL | D12: 20 | E12: =COUNTIF($B$2:B12, B12) -> 1 | F12: 0 | G12: 0 | H12: 1 | I12: =SUM(G12:H12) -> 1 | L12: 1 | M12: 1 | N12: 0 | O12: SR l
A13: 11 | B13: ATL218_dir-sag | C13: dataset-ATL | D13: 20 | E13: =COUNTIF($B$2:B13, B13) -> 1 | F13: 0 | G13: 0 | H13: 0 | I13: =SUM(G13:H13) -> 0 | L13: 1 | M13: 0 | N13: 0 | O13: Type 4 → Lumbar
... A23: 21 | B23: ced0119_ses-20091112_sequ-7_ce-no | C23: dataset-ced | D23: 20 | E23: =COUNTIF($B$2:B23, B23) -> 1 | F23: 0 | G23: 0 | H23: 1 | I23: =SUM(G23:H23) -> 1 | L23: 1 | M23: 1 | N23: 1 | O23: SR bds
A24: 22 | B24: ced0123_ses-20190108_sequ-201_ce-pv | C24: dataset-ced | D24: 18 | E24: =COUNTIF($B$2:B24, B24) -> 1 | F24: 1 | I24: =SUM(G24:H24) -> 0 | O24: Kompletter segfail
A25: 23 | B25: ced0153_ses-20110119_sequ-401_ce-pv | C25: dataset-ced | D25: 20 | E25: =COUNTIF($B$2:B25, B25) -> 1 | F25: 0 | G25: 0 | H25: 1 | I25: =SUM(G25:H25) -> 1 | L25: 1 | M25: 1 | N25: 1 | O25: SUPER EDGE CASE unsicher
A26: 24 | B26: ced0161_ses-20200720_sequ-10_ce-pv | C26: dataset-ced | D26: 20 | E26: =COUNTIF($B$2:B26, B26) -> 1 | F26: 0 | G26: 0 | H26: 0 | I26: =SUM(G26:H26) -> 0 | L26: 0 | M26: 0 | N26: 0 | O26: Keine Rippen
A27: 25 | B27: ced0207_ses-20160624_sequ-201_ce-no | C27: dataset-ced | D27: 20 | E27: =COUNTIF($B$2:B27, B27) -> 1 | F27: 0 | G27: 0 | H27: 0 | I27: =SUM(G27:H27) -> 0 | L27: 1 | M27: 1 | N27: 1 | O27: Metal, schwer, aber Normaler 12/5
A28: 26 | B28: ced0209_ses-20130703_sequ-2_ce-no | C28: dataset-ced | D28: 19 | E28: =COUNTIF($B$2:B28, B28) -> 1 | F28: 0 | G28: 0 | H28: 0 | I28: =SUM(G28:H28) -> 0 | J28: [9, 10, 11, 12, 13, 14, 15, 16, 17, 18, 19, 28, 20, 21, 22, 23] | L28: 0 | M28: 0 | N28: 0 | O28: Rippen, bleibt T12
A29: 27 | B29: ced0264_ses-20120919_sequ-4_ce-pv | C29: dataset-ced | D29: 20 | E29: =COUNTIF($B$2:B29, B29) -> 1 | F29: 0 | G29: 0 | H29: 0 | I29: =SUM(G29:H29) -> 0 | J29: [6, 7, 8, 9, 10, 11, 12, 13, 14, 15, 16, 17, 18, 19, 20, 21, 22, 23] | L29: 1 | M29: 1 | N29: 1 | O29: SR bds
A30: 28 | B30: ced0295_ses-20200815_sequ-201_ce-no | C30: dataset-ced | D30: 20 | E30: =COUNTIF($B$2:B30, B30) -> 1 | F30: 0 | G30: 0 | H30: 0 | I30: =SUM(G30:H30) -> 0 | L30: 0 | M30: 0 | N30: 0 | O30: Keine Rippen
A31: 29 | B31: ced0358_ses-20171214_sequ-202_ce-no | C31: dataset-ced | D31: 19 | E31: =COUNTIF($B$2:B31, B31) -> 1 | F31: 1 | G31: 0 | H31: 0 | I31: =SUM(G31:H31) -> 0 | L31: 0 | M31: 0 | N31: 0 | O31: Keine Rippen, T11, T3 MERGED
A32: 30 | B32: ced0365_ses-20120418_sequ-3_ce-no | C32: dataset-ced | D32: 20 | E32: =COUNTIF($B$2:B32, B32) -> 1 | F32: 0 | G32: 0 | H32: 1 | I32: =SUM(G32:H32) -> 1 | L32: 1 | M32: 1 | N32: 1 | O32: SR bds
A33: 31 | B33: ced0365_ses-20200415_sequ-205_ce-no | C33: dataset-ced | D33: 20 | E33: =COUNTIF($B$2:B33, B33) -> 1 | F33: 0 | G33: 0 | H33: 0 | I33: =SUM(G33:H33) -> 0 | J33: [8, 9, 10, 11, 12, 13, 14, 15, 16, 17, 18, 19, 28, 20, 21, 22, 23] | L33: 0 | M33: 0 | N33: 0 | O33: Keine Rippen
A34: 32 | B34: ced0429_ses-20070614_sequ-4_ce-pv | C34: dataset-ced | D34: 19 | E34: =COUNTIF($B$2:B34, B34) -> 1 | F34: 0 | G34: 0 | H34: 0 | I34: =SUM(G34:H34) -> 0 | J34: [9, 10, 11, 12, 13, 14, 15, 16, 17, 18, 19, 20, 21, 22, 23, 24] | O34: Keine Rippen, T11
A35: 33 | B35: gl3109354 | C35: dataset-CSILabel | D35: 20 | E35: =COUNTIF($B$2:B35, B35) -> 1 | F35: 0 | G35: 0 | H35: 0 | I35: =SUM(G35:H35) -> 0 | L35: 0 | M35: 0 | N35: 0 | O35: Passt
A36: 34 | B36: csi013 | C36: dataset-CSIsegment | D36: 20 | E36: =COUNTIF($B$2:B36, B36) -> 1 | F36: 0 | G36: 0 | H36: 1 | I36: =SUM(G36:H36) -> 1 | L36: 1 | M36: 1 | N36: 1 | O36: SR bds
A37: 35 | B37: ctfu00088_ses-20171222_ce-no | C37: dataset-ctfu1org | D37: 20 | E37: =COUNTIF($B$2:B37, B37) -> 1 | F37: 0 | G37: 0 | H37: 1 | I37: =SUM(G37:H37) -> 1 | L37: 1 | M37: 1 | N37: 1 | O37: SR bds
A38: 36 | B38: ctfu00222_ses-20090626_ce-pv | C38: dataset-ctfu1org | D38: 20 | E38: =COUNTIF($B$2:B38, B38) -> 1 | F38: 0 | G38: 0 | H38: 1 | I38: =SUM(G38:H38) -> 1 | L38: 1 | M38: 1 | N38: 1 | O38: SR bds
A39: 37 | B39: ctfu00273_ses-20150210_ce-pv | C39: dataset-ctfu1org | D39: 20 | E39: =COUNTIF($B$2:B39, B39) -> 1 | F39: 0 | G39: 0 | H39: 1 | I39: =SUM(G39:H39) -> 1 | L39: 1 | M39: 1 | N39: 1 | O39: SR bds
A40: 38 | B40: ctfu00299_ses-20070625_ce-pv | C40: dataset-ctfu1org | D40: 20 | E40: =COUNTIF($B$2:B40, B40) -> 1 | F40: 0 | G40: 0 | H40: 0 | I40: =SUM(G40:H40) -> 0 | L40: 0 | M40: 0 | N40: 0 | O40: Keine Rippen
A41: 39 | B41: ctfu00303_ses-20060928_ce-art | C41: dataset-ctfu1org | D41: 20 | E41: =COUNTIF($B$2:B41, B41) -> 1 | F41: 0 | G41: 0 | H41: 0 | I41: =SUM(G41:H41) -> 0 | O41: Passt 8 start ohne T13 aber normal L4 | P41: [9, 10, 11, 12, 13, 14, 15, 16, 17, 18, 19, 28, 20, 21, 22, 23]
A42: 40 | B42: ctfu00369_ses-20170315_ce-pv | C42: dataset-ctfu1org | D42: 20 | E42: =COUNTIF($B$2:B42, B42) -> 1 | F42: 0 | G42: 0 | H42: 0 | I42: =SUM(G42:H42) -> 0 | L42: 0 | M42: 0 | N42: 0 | O42: Keine Rippen
A43: 41 | B43: ctfu00423_ses-20140225_ce-art | C43: dataset-ctfu1org | D43: 20 | E43: =COUNTIF($B$2:B43, B43) -> 1 | F43: 0 | G43: 0 | H43: 0 | I43: =SUM(G43:H43) -> 0 | L43: 0 | M43: 0 | N43: 0 | O43: Keine Rippen
A44: 42 | B44: ctfu00469_ses-20070904_ce-pv | C44: dataset-ctfu1org | D44: 20 | E44: =COUNTIF($B$2:B44, B44) -> 1 | F44: 0 | G44: 0 | H44: 1 | I44: =SUM(G44:H44) -> 1 | L44: 1 | M44: 1 | N44: 1 | O44: SR bds, arg abgeschnitten seitlich
A45: 43 | B45: ctfu00506_ses-20070822_ce-pv | C45: dataset-ctfu1org | D45: 20 | E45: =COUNTIF($B$2:B45, B45) -> 1 | F45: 0 | G45: 0 | H45: 0 | I45: =SUM(G45:H45) -> 0 | L45: 0 | M45: 0 | N45: 0 | O45: Keine Rippen
A46: 44 | B46: ctfu00509_ses-20060725_ce-pv | C46: dataset-ctfu1org | D46: 20 | E46: =COUNTIF($B$2:B46, B46) -> 1 | F46: 0 | G46: 0 | H46: 1 | I46: =SUM(G46:H46) -> 1 | L46: 1 | M46: 1 | N46: 1 | O46: SR bds
A47: 45 | B47: ctfu00531_ses-20120702_ce-art | C47: dataset-ctfu1org | D47: 20 | E47: =COUNTIF($B$2:B47, B47) -> 1 | F47: 0 | G47: 0 | H47: 0 | I47: =SUM(G47:H47) -> 0 | L47: 1 | M47: 0 | N47: 1 | O47: Type 4 -> lumbar
A48: 46 | B48: ctfu00538_ses-20150306_ce-pv | C48: dataset-ctfu1org | D48: 20 | E48: =COUNTIF($B$2:B48, B48) -> 1 | F48: 0 | G48: 0 | H48: 1 | I48: =SUM(G48:H48) -> 1 | L48: 1 | M48: 1 | N48: 1 | O48: SR bds
A49: 47 | B49: ctfu00544_ses-20090310_ce-pv | C49: dataset-ctfu1org | D49: 20 | E49: =COUNTIF($B$2:B49, B49) -> 1 | F49: 0 | G49: 0 | H49: 1 | I49: =SUM(G49:H49) -> 1 | L49: 1 | M49: 1 | N49: 1 | O49: SUPER EDGE CASE unsicher
...

Sheet Statistics
A1: Block | B1: All | C1: dataset-ATL | D1: dataset-ced | E1: dataset-CSILabel | F1: dataset-ctfu1org | G1: dataset-CTSp1k | H1: dataset-fxclass | I1: dataset-gl | J1: dataset-rsna_org | K1: dataset-sagthomas | L1: dataset-tri | M1: dataset-verse19 | N1: Dataset-verse20 | O1: dataset-xvertsegCropped
A2: Number entries | B2: =SUM(C2:O2) -> 196 | C2: =COUNTIF(Sheet1!$C$2:$C$11473,C1) -> 18 | D2: =COUNTIF(Sheet1!$C$2:$C$11473,D1) -> 15 | E2: =COUNTIF(Sheet1!$C$2:$C$11473,E1) -> 1 | F2: =COUNTIF(Sheet1!$C$2:$C$11473,F1) -> 32 | G2: =COUNTIF(Sheet1!$C$2:$C$11473,G1) -> 18 | H2: =COUNTIF(Sheet1!$C$2:$C$11473,H1) -> 29 | I2: =COUNTIF(Sheet1!$C$2:$C$11473,I1) -> 0 | J2: =COUNTIF(Sheet1!$C$2:$C$11473,J1) -> 0 | ... O2: =COUNTIF(Sheet1!$C$2:$C$11473,O1) -> 0
A3: Number patients (m) | B3: =SUM(C3:O3) -> 3776 | C3: 202 | D3: 462 | E3: 86 | F3: 465 | G3: 883 | H3: 405 | I3: 29 | J3: 86 | K3: 444 | L3: 370 | M3: 157 | N3: 172 | O3: 15
A4: N_ANY | B4: =SUM(C4:O4) -> 104 | C4: =SUM(C6:C8) -> 13 | D4: =SUM(D6:D8) -> 9 | E4: =SUM(E6:E8) -> 1 | F4: =SUM(F6:F8) -> 15 | G4: =SUM(G6:G8) -> 7 | H4: =SUM(H6:H8) -> 13 | I4: =SUM(I6:I8) -> 0 | J4: =SUM(J6:J8) -> 0 | ... O4: =SUM(O6:O8) -> 0
A5: N_TEA_Anomaly | B5: =SUM(C5:O5) -> 92 | C5: =C6+C7 -> 11 | D5: =D6+D7 -> 6 | E5: =E6+E7 -> 0 | F5: =F6+F7 -> 14 | G5: =G6+G7 -> 7 | H5: =H6+H7 -> 12 | I5: =I6+I7 -> 0 | J5: =J6+J7 -> 0 | ... O5: =O6+O7 -> 0
A6: N_T11 | B6: =SUM(C6:O6) -> 1 | C6: =COUNTIFS(Sheet1!$C$2:$C$1236,C1,Sheet1!$G$2:$G$1236,1) -> 0 | D6: =COUNTIFS(Sheet1!$C$2:$C$1236,D1,Sheet1!$G$2:$G$1236,1) -> 0 | E6: =COUNTIFS(Sheet1!$C$2:$C$1236,E1,Sheet1!$G$2:$G$1236,1) -> 0 | F6: =COUNTIFS(Sheet1!$C$2:$C$1236,F1,Sheet1!$G$2:$G$1236,1) -> 0 | G6: =COUNTIFS(Sheet1!$C$2:$C$1236,G1,Sheet1!$G$2:$G$1236,1) -> 0 | H6: =COUNTIFS(Sheet1!$C$2:$C$1236,H1,Sheet1!$G$2:$G$1236,1) -> 1 | I6: =COUNTIFS(Sheet1!$C$2:$C$1236,I1,Sheet1!$G$2:$G$1236,1) -> 0 | J6: =COUNTIFS(Sheet1!$C$2:$C$1236,J1,Sheet1!$G$2:$G$1236,1) -> 0 | ... O6: =COUNTIFS(Sheet1!$C$2:$C$1236,O1,Sheet1!$G$2:$G$1236,1) -> 0
A7: N_T13 | B7: =SUM(C7:O7) -> 91 | C7: =COUNTIFS(Sheet1!$C$2:$C$1236,C1,Sheet1!$H$2:$H$1236,1) -> 11 | D7: =COUNTIFS(Sheet1!$C$2:$C$1236,D1,Sheet1!$H$2:$H$1236,1) -> 6 | E7: =COUNTIFS(Sheet1!$C$2:$C$1236,E1,Sheet1!$H$2:$H$1236,1) -> 0 | F7: =COUNTIFS(Sheet1!$C$2:$C$1236,F1,Sheet1!$H$2:$H$1236,1) -> 14 | G7: =COUNTIFS(Sheet1!$C$2:$C$1236,G1,Sheet1!$H$2:$H$1236,1) -> 7 | H7: =COUNTIFS(Sheet1!$C$2:$C$1236,H1,Sheet1!$H$2:$H$1236,1) -> 11 | I7: =COUNTIFS(Sheet1!$C$2:$C$1236,I1,Sheet1!$H$2:$H$1236,1) -> 0 | J7: =COUNTIFS(Sheet1!$C$2:$C$1236,J1,Sheet1!$H$2:$H$1236,1) -> 0 | ... O7: =COUNTIFS(Sheet1!$C$2:$C$1236,O1,Sheet1!$H$2:$H$1236,1) -> 0
A8: N_Remove | B8: =SUM(C8:O8) -> 12 | C8: =SUM(F8:J8) -> 2 | D8: =K8 -> 3 | E8: =SUM(L8:M8) -> 1 | F8: =COUNTIFS(Sheet1!$C$2:$C$1236,F1,Sheet1!$F$2:$F$1236,1) -> 1 | G8: =COUNTIFS(Sheet1!$C$2:$C$1236,G1,Sheet1!$F$2:$F$1236,1) -> 0 | H8: =COUNTIFS(Sheet1!$C$2:$C$1236,H1,Sheet1!$F$2:$F$1236,1) -> 1 | I8: =COUNTIFS(Sheet1!$C$2:$C$1236,I1,Sheet1!$F$2:$F$1236,1) -> 0 | J8: =COUNTIFS(Sheet1!$C$2:$C$1236,J1,Sheet1!$F$2:$F$1236,1) -> 0 | K8: =COUNTIFS(Sheet1!$C$2:$C$1236,K1,Sheet1!$F$2:$F$1236,1) -> 3 | L8: =COUNTIFS(Sheet1!$C$2:$C$1236,L1,Sheet1!$F$2:$F$1236,1) -> 1 | M8: =COUNTIFS(Sheet1!$C$2:$C$1236,M1,Sheet1!$F$2:$F$1236,1) -> 0 | ... O8: =COUNTIFS(Sheet1!$C$2:$C$1236,O1,Sheet1!$F$2:$F$1236,1) -> 0
A9: N_TLTV | B9: =SUM(C9:O9) -> 109 | C9: =COUNTIFS(Sheet1!$C$2:$C$1236,C1,Sheet1!$L$2:$L$1236,1) -> 13 | D9: =COUNTIFS(Sheet1!$C$2:$C$1236,D1,Sheet1!$L$2:$L$1236,1) -> 8 | E9: =COUNTIFS(Sheet1!$C$2:$C$1236,E1,Sheet1!$L$2:$L$1236,1) -> 0 | F9: =COUNTIFS(Sheet1!$C$2:$C$1236,F1,Sheet1!$L$2:$L$1236,1) -> 15 | G9: =COUNTIFS(Sheet1!$C$2:$C$1236,G1,Sheet1!$L$2:$L$1236,1) -> 7 | H9: =COUNTIFS(Sheet1!$C$2:$C$1236,H1,Sheet1!$L$2:$L$1236,1) -> 17 | I9: =COUNTIFS(Sheet1!$C$2:$C$1236,I1,Sheet1!$L$2:$L$1236,1) -> 0 | J9: =COUNTIFS(Sheet1!$C$2:$C$1236,J1,Sheet1!$L$2:$L$1236,1) -> 0 | ... O9: =COUNTIFS(Sheet1!$C$2:$C$1236,O1,Sheet1!$L$2:$L$1236,1) -> 0
D10: =K10 -> 0
A11: Rel to Patients | D11: =K11 -> 0
A12: % ANY | B12: =ROUND(B4 / B$3, 4) * 100 -> 2.75 | C12: =ROUND(C4 / C$3, 4) * 100 -> 6.44 | D12: =K12 -> 6.98 | E12: =ROUND(E4 / E$3, 4) * 100 -> 1.16 | F12: =ROUND(F4 / F$3, 4) * 100 -> 3.23 | G12: =ROUND(G4 / G$3, 4) * 100 -> 0.79 | H12: =ROUND(H4 / H$3, 4) * 100 -> 3.21 | I12: =ROUND(I4 / I$3, 4) * 100 -> 0 | J12: =ROUND(J4 / J$3, 4) * 100 -> 0 | K12: =ROUND(K4 / K$3, 4) * 100 -> 6.98 | L12: =ROUND(L4 / L$3, 4) * 100 -> 0.27 | ... O12: =ROUND(O4 / O$3, 4) * 100 -> 0
A13: % TEA_Anomaly | B13: =ROUND(B5 / B$3, 4) * 100 -> 2.44 | C13: =ROUND(C5 / C$3, 4) * 100 -> 5.45 | D13: =K13 -> 6.31 | E13: =ROUND(E5 / E$3, 4) * 100 -> 0 | F13: =ROUND(F5 / F$3, 4) * 100 -> 3.01 | G13: =ROUND(G5 / G$3, 4) * 100 -> 0.79 | H13: =ROUND(H5 / H$3, 4) * 100 -> 2.96 | I13: =ROUND(I5 / I$3, 4) * 100 -> 0 | J13: =ROUND(J5 / J$3, 4) * 100 -> 0 | K13: =ROUND(K5 / K$3, 4) * 100 -> 6.31 | L13: =ROUND(L5 / L$3, 4) * 100 -> 0 | ... O13: =ROUND(O5 / O$3, 4) * 100 -> 0
A14: % T11 | B14: =ROUND(B6 / B$3, 4) * 100 -> 0.03 | C14: =ROUND(C6 / C$3, 4) * 100 -> 0 | D14: =K14 -> 0 | E14: =ROUND(E6 / E$3, 4) * 100 -> 0 | F14: =ROUND(F6 / F$3, 4) * 100 -> 0 | G14: =ROUND(G6 / G$3, 4) * 100 -> 0 | H14: =ROUND(H6 / H$3, 4) * 100 -> 0.25 | I14: =ROUND(I6 / I$3, 4) * 100 -> 0 | J14: =ROUND(J6 / J$3, 4) * 100 -> 0 | K14: =ROUND(K6 / K$3, 4) * 100 -> 0 | L14: =ROUND(L6 / L$3, 4) * 100 -> 0 | ... O14: =ROUND(O6 / O$3, 4) * 100 -> 0
A15: % T13 | B15: =ROUND(B7 / B$3, 4) * 100 -> 2.41 | C15: =ROUND(C7 / C$3, 4) * 100 -> 5.45 | D15: =K15 -> 6.31 | E15: =ROUND(E7 / E$3, 4) * 100 -> 0 | F15: =ROUND(F7 / F$3, 4) * 100 -> 3.01 | G15: =ROUND(G7 / G$3, 4) * 100 -> 0.79 | H15: =ROUND(H7 / H$3, 4) * 100 -> 2.72 | I15: =ROUND(I7 / I$3, 4) * 100 -> 0 | J15: =ROUND(J7 / J$3, 4) * 100 -> 0 | K15: =ROUND(K7 / K$3, 4) * 100 -> 6.31 | L15: =ROUND(L7 / L$3, 4) * 100 -> 0 | ... O15: =ROUND(O7 / O$3, 4) * 100 -> 0
A16: % Remove | B16: =ROUND(B8 / B$3, 4) * 100 -> 0.32 | C16: =ROUND(C8 / C$3, 4) * 100 -> 0.99 | D16: =K16 -> 0.68 | E16: =ROUND(E8 / E$3, 4) * 100 -> 1.16 | F16: =ROUND(F8 / F$3, 4) * 100 -> 0.22 | G16: =ROUND(G8 / G$3, 4) * 100 -> 0 | H16: =ROUND(H8 / H$3, 4) * 100 -> 0.25 | I16: =ROUND(I8 / I$3, 4) * 100 -> 0 | J16: =ROUND(J8 / J$3, 4) * 100 -> 0 | K16: =ROUND(K8 / K$3, 4) * 100 -> 0.68 | L16: =ROUND(L8 / L$3, 4) * 100 -> 0.27 | ... O16: =ROUND(O8 / O$3, 4) * 100 -> 0
A17: % TLTV | B17: =ROUND(B9 / B$3, 4) * 100 -> 2.89 | C17: =ROUND(C9 / C$3, 4) * 100 -> 6.44 | D17: =K17 -> 7.43 | E17: =ROUND(E9 / E$3, 4) * 100 -> 0 | F17: =ROUND(F9 / F$3, 4) * 100 -> 3.23 | G17: =ROUND(G9 / G$3, 4) * 100 -> 0.79 | H17: =ROUND(H9 / H$3, 4) * 100 -> 4.2 | I17: =ROUND(I9 / I$3, 4) * 100 -> 0 | J17: =ROUND(J9 / J$3, 4) * 100 -> 0 | K17: =ROUND(K9 / K$3, 4) * 100 -> 7.43 | L17: =ROUND(L9 / L$3, 4) * 100 -> 0 | ... O17: =ROUND(O9 / O$3, 4) * 100 -> 0
D18: =K18 -> 0
A19: Rel to entries | D19: =K19 -> 0
A20: % ANY | B20: =ROUND(B4 / B$2, 4) * 100 -> 53.06 | C20: =ROUND(C4 / C$2, 4) * 100 -> 72.22 | D20: =K20 -> 54.39 | E20: =ROUND(E4 / E$2, 4) * 100 -> 100 | F20: =ROUND(F4 / F$2, 4) * 100 -> 46.88 | G20: =ROUND(G4 / G$2, 4) * 100 -> 38.89 | H20: =ROUND(H4 / H$2, 4) * 100 -> 44.83 | I20: =ROUND(I4 / I$2, 4) * 100 -> #DIV/0! | J20: =ROUND(J4 / J$2, 4) * 100 -> #DIV/0! | K20: =ROUND(K4 / K$2, 4) * 100 -> 54.39 | L20: =ROUND(L4 / L$2, 4) * 100 -> 100 | ... O20: =ROUND(O4 / O$2, 4) * 100 -> #DIV/0!
A21: % TEA_Anomaly | B21: =ROUND(B5 / B$2, 4) * 100 -> 46.94 | C21: =ROUND(C5 / C$2, 4) * 100 -> 61.11 | D21: =K21 -> 49.12 | E21: =ROUND(E5 / E$2, 4) * 100 -> 0 | F21: =ROUND(F5 / F$2, 4) * 100 -> 43.75 | G21: =ROUND(G5 / G$2, 4) * 100 -> 38.89 | H21: =ROUND(H5 / H$2, 4) * 100 -> 41.38 | I21: =ROUND(I5 / I$2, 4) * 100 -> #DIV/0! | J21: =ROUND(J5 / J$2, 4) * 100 -> #DIV/0! | K21: =ROUND(K5 / K$2, 4) * 100 -> 49.12 | L21: =ROUND(L5 / L$2, 4) * 100 -> 0 | ... O21: =ROUND(O5 / O$2, 4) * 100 -> #DIV/0!
A22: % T11 | B22: =ROUND(B6 / B$2, 4) * 100 -> 0.51 | C22: =ROUND(C6 / C$2, 4) * 100 -> 0 | D22: =K22 -> 0 | E22: =ROUND(E6 / E$2, 4) * 100 -> 0 | F22: =ROUND(F6 / F$2, 4) * 100 -> 0 | G22: =ROUND(G6 / G$2, 4) * 100 -> 0 | H22: =ROUND(H6 / H$2, 4) * 100 -> 3.45 | I22: =ROUND(I6 / I$2, 4) * 100 -> #DIV/0! | J22: =ROUND(J6 / J$2, 4) * 100 -> #DIV/0! | K22: =ROUND(K6 / K$2, 4) * 100 -> 0 | L22: =ROUND(L6 / L$2, 4) * 100 -> 0 | ... O22: =ROUND(O6 / O$2, 4) * 100 -> #DIV/0!
A23: % T13 | B23: =ROUND(B7 / B$2, 4) * 100 -> 46.43 | C23: =ROUND(C7 / C$2, 4) * 100 -> 61.11 | D23: =K23 -> 49.12 | E23: =ROUND(E7 / E$2, 4) * 100 -> 0 | F23: =ROUND(F7 / F$2, 4) * 100 -> 43.75 | G23: =ROUND(G7 / G$2, 4) * 100 -> 38.89 | H23: =ROUND(H7 / H$2, 4) * 100 -> 37.93 | I23: =ROUND(I7 / I$2, 4) * 100 -> #DIV/0! | J23: =ROUND(J7 / J$2, 4) * 100 -> #DIV/0! | K23: =ROUND(K7 / K$2, 4) * 100 -> 49.12 | L23: =ROUND(L7 / L$2, 4) * 100 -> 0 | ... O23: =ROUND(O7 / O$2, 4) * 100 -> #DIV/0!
A24: % Remove | B24: =ROUND(B8 / B$2, 4) * 100 -> 6.12 | C24: =ROUND(C8 / C$2, 4) * 100 -> 11.11 | D24: =K24 -> 5.26 | E24: =ROUND(E8 / E$2, 4) * 100 -> 100 | F24: =ROUND(F8 / F$2, 4) * 100 -> 3.13 | G24: =ROUND(G8 / G$2, 4) * 100 -> 0 | H24: =ROUND(H8 / H$2, 4) * 100 -> 3.45 | I24: =ROUND(I8 / I$2, 4) * 100 -> #DIV/0! | J24: =ROUND(J8 / J$2, 4) * 100 -> #DIV/0! | K24: =ROUND(K8 / K$2, 4) * 100 -> 5.26 | L24: =ROUND(L8 / L$2, 4) * 100 -> 100 | ... O24: =ROUND(O8 / O$2, 4) * 100 -> #DIV/0!
A25: % TLTV | B25: =ROUND(B9 / B$2, 4) * 100 -> 55.61 | C25: =ROUND(C9 / C$2, 4) * 100 -> 72.22 | D25: =K25 -> 57.89 | E25: =ROUND(E9 / E$2, 4) * 100 -> 0 | F25: =ROUND(F9 / F$2, 4) * 100 -> 46.88 | G25: =ROUND(G9 / G$2, 4) * 100 -> 38.89 | H25: =ROUND(H9 / H$2, 4) * 100 -> 58.62 | I25: =ROUND(I9 / I$2, 4) * 100 -> #DIV/0! | J25: =ROUND(J9 / J$2, 4) * 100 -> #DIV/0! | K25: =ROUND(K9 / K$2, 4) * 100 -> 57.89 | L25: =ROUND(L9 / L$2, 4) * 100 -> 0 | ... O25: =ROUND(O9 / O$2, 4) * 100 -> #DIV/0!
